Workbook

Sheet 1. README
A1: EnergyLens — 3-Year Revenue Model
A3: Created | B3: 2026-05-15
A4: Author | B4: Ali Mert Özdemir, Founder
A5: Purpose | B5: Microsoft for Startups Founders Hub application
A6: Currency | B6: EUR (€)
A7: Period | B7: Q3 2026 — Q2 2029 (3 years)
A9: MODEL STRUCTURE
A10: Sheet 2 — Assumptions | B10: All input parameters (prices, growth rates, costs). Blue cells = editable inputs.
A11: Sheet 3 — Customer Build | B11: Quarterly customer acquisition forecast across 3 years
A12: Sheet 4 — Revenue | B12: Per-quarter revenue calculation, derived from customer count × pricing
A13: Sheet 5 — Costs | B13: Infrastructure, marketing, salaries, total cost structure
A14: Sheet 6 — P&L Summary | B14: 3-year profit & loss with cumulative cash flow
A15: Sheet 7 — Microsoft Ask | B15: Specific Microsoft for Startups credit utilization
A17: COLOR CONVENTIONS
A18: Blue text | B18: Hardcoded input — editable, recalculates dependent formulas
A19: Black text | B19: Formula — derived from inputs, do not edit directly
A20: Green text | B20: Cross-sheet reference
A21: Yellow fill | B21: Key assumption requiring scenario review
A23: KEY HEADLINE NUMBERS (computed in P&L)
A24: Year 3 ARR | B24: ='6. P&L Summary'!D11 -> 6258924
A25: Year 3 Customers | B25: ='6. P&L Summary'!D6 -> 141
A26: Cumulative 3-Yr Revenue | B26: ='6. P&L Summary'!F10 -> 5980047
A27: Cumulative 3-Yr Net | B27: ='6. P&L Summary'!F15 -> 5491597

Sheet 2. Assumptions
A1: Assumptions — All Inputs
A3: PRICING (per building per month, EUR)
A4: Insight tier | B4: 99 | C4: SME offices <5,000 m²
A5: Monitor tier | B5: 299 | C5: Mid-market property mgmt
A6: Copilot tier | B6: 699 | C6: Enterprise, healthcare, hotels
A7: Enterprise Custom (avg) | B7: 1500 | C7: REITs, large portfolios — average per building
A9: CUSTOMER MIX BY TIER (Year 1 / 2 / 3)
A10: Tier | B10: Year 1 | C10: Year 2 | D10: Year 3
A11: Insight % | B11: 0.5 | C11: 0.4 | D11: 0.3
A12: Monitor % | B12: 0.4 | C12: 0.45 | D12: 0.45
A13: Copilot % | B13: 0.1 | C13: 0.13 | D13: 0.2
A14: Enterprise % | B14: 0 | C14: 0.02 | D14: 0.05
A15: Total (should = 100%) | B15: =SUM(B11:B14) -> 1 | C15: =SUM(C11:C14) -> 1 | D15: =SUM(D11:D14) -> 1
A17: AVG BUILDINGS PER CUSTOMER
A18: Insight customers | B18: 2
A19: Monitor customers | B19: 5
A20: Copilot customers | B20: 8
A21: Enterprise customers | B21: 25
A23: QUARTERLY NEW CUSTOMER ACQUISITION
A24: Quarter | B24: New customers | C24: Cumulative | D24: Churn % qtr
A25: Q3 2026 | B25: 1 | C25: =B25 -> 1 | D25: 0
A26: Q4 2026 | B26: 3 | C26: =C25+B26-ROUND(C25*D26,0) -> 4 | D26: 0
A27: Q1 2027 | B27: 4 | C27: =C26+B27-ROUND(C26*D27,0) -> 8 | D27: 0.025
A28: Q2 2027 | B28: 6 | C28: =C27+B28-ROUND(C27*D28,0) -> 14 | D28: 0.025
A29: Q3 2027 | B29: 8 | C29: =C28+B29-ROUND(C28*D29,0) -> 22 | D29: 0.025
A30: Q4 2027 | B30: 10 | C30: =C29+B30-ROUND(C29*D30,0) -> 31 | D30: 0.025
A31: Q1 2028 | B31: 14 | C31: =C30+B31-ROUND(C30*D31,0) -> 44 | D31: 0.03
A32: Q2 2028 | B32: 16 | C32: =C31+B32-ROUND(C31*D32,0) -> 59 | D32: 0.03
A33: Q3 2028 | B33: 18 | C33: =C32+B33-ROUND(C32*D33,0) -> 75 | D33: 0.03
A34: Q4 2028 | B34: 22 | C34: =C33+B34-ROUND(C33*D34,0) -> 95 | D34: 0.03
A35: Q1 2029 | B35: 25 | C35: =C34+B35-ROUND(C34*D35,0) -> 117 | D35: 0.03
A36: Q2 2029 | B36: 28 | C36: =C35+B36-ROUND(C35*D36,0) -> 141 | D36: 0.03
A39: COST ASSUMPTIONS (monthly EUR)
A40: Microsoft Fabric capacity (post-Startups credit) | B40: 0 | C40: Startups Tier 2 covers Year 1
A41: Microsoft Fabric capacity (Year 2+) | B41: 400 | C41: F8 SKU after credit expires
A42: Azure infrastructure (web app, DB) | B42: 100 | C42: Container Apps + PostgreSQL + Static Web App
A43: Tools (LinkedIn Premium, ElevenLabs, etc.) | B43: 150 | C43: Sales tools + dev tools
A44: Marketing spend | B44: 300 | C44: LinkedIn ads, conferences, content
A45: Domain + administrative | B45: 50 | C45: Domain renewal + UG mini-GmbH overhead
A48: TEAM SALARY (annual EUR, gross)
...

Sheet 3. Customers
A1: Customer Build — Quarterly Forecast
A3: Metric | B3: Q3'26 | C3: Q4'26 | D3: Q1'27 | E3: Q2'27 | F3: Q3'27 | G3: Q4'27 | H3: Q1'28 | I3: Q2'28 | J3: Q3'28 | K3: Q4'28 | L3: Q1'29 | M3: Q2'29
A4: Total customers (cumulative) | B4: ='2. Assumptions'!C25 -> 1 | C4: ='2. Assumptions'!C26 -> 4 | D4: ='2. Assumptions'!C27 -> 8 | E4: ='2. Assumptions'!C28 -> 14 | F4: ='2. Assumptions'!C29 -> 22 | G4: ='2. Assumptions'!C30 -> 31 | H4: ='2. Assumptions'!C31 -> 44 | I4: ='2. Assumptions'!C32 -> 59 | J4: ='2. Assumptions'!C33 -> 75 | K4: ='2. Assumptions'!C34 -> 95 | L4: ='2. Assumptions'!C35 -> 117 | M4: ='2. Assumptions'!C36 -> 141
A5: Insight customers | B5: =ROUND(B4*'2. Assumptions'!B11,0) -> 1 | C5: =ROUND(C4*'2. Assumptions'!B11,0) -> 2 | D5: =ROUND(D4*'2. Assumptions'!B11,0) -> 4 | E5: =ROUND(E4*'2. Assumptions'!B11,0) -> 7 | F5: =ROUND(F4*'2. Assumptions'!C11,0) -> 9 | G5: =ROUND(G4*'2. Assumptions'!C11,0) -> 12 | H5: =ROUND(H4*'2. Assumptions'!C11,0) -> 18 | I5: =ROUND(I4*'2. Assumptions'!C11,0) -> 24 | J5: =ROUND(J4*'2. Assumptions'!D11,0) -> 23 | K5: =ROUND(K4*'2. Assumptions'!D11,0) -> 29 | L5: =ROUND(L4*'2. Assumptions'!D11,0) -> 35 | M5: =ROUND(M4*'2. Assumptions'!D11,0) -> 42
A6: Monitor customers | B6: =ROUND(B4*'2. Assumptions'!B12,0) -> 0 | C6: =ROUND(C4*'2. Assumptions'!B12,0) -> 2 | D6: =ROUND(D4*'2. Assumptions'!B12,0) -> 3 | E6: =ROUND(E4*'2. Assumptions'!B12,0) -> 6 | F6: =ROUND(F4*'2. Assumptions'!C12,0) -> 10 | G6: =ROUND(G4*'2. Assumptions'!C12,0) -> 14 | H6: =ROUND(H4*'2. Assumptions'!C12,0) -> 20 | I6: =ROUND(I4*'2. Assumptions'!C12,0) -> 27 | J6: =ROUND(J4*'2. Assumptions'!D12,0) -> 34 | K6: =ROUND(K4*'2. Assumptions'!D12,0) -> 43 | L6: =ROUND(L4*'2. Assumptions'!D12,0) -> 53 | M6: =ROUND(M4*'2. Assumptions'!D12,0) -> 63
A7: Copilot customers | B7: =ROUND(B4*'2. Assumptions'!B13,0) -> 0 | C7: =ROUND(C4*'2. Assumptions'!B13,0) -> 0 | D7: =ROUND(D4*'2. Assumptions'!B13,0) -> 1 | E7: =ROUND(E4*'2. Assumptions'!B13,0) -> 1 | F7: =ROUND(F4*'2. Assumptions'!C13,0) -> 3 | G7: =ROUND(G4*'2. Assumptions'!C13,0) -> 4 | H7: =ROUND(H4*'2. Assumptions'!C13,0) -> 6 | I7: =ROUND(I4*'2. Assumptions'!C13,0) -> 8 | J7: =ROUND(J4*'2. Assumptions'!D13,0) -> 15 | K7: =ROUND(K4*'2. Assumptions'!D13,0) -> 19 | L7: =ROUND(L4*'2. Assumptions'!D13,0) -> 23 | M7: =ROUND(M4*'2. Assumptions'!D13,0) -> 28
A8: Enterprise customers | B8: =ROUND(B4*'2. Assumptions'!B14,0) -> 0 | C8: =ROUND(C4*'2. Assumptions'!B14,0) -> 0 | D8: =ROUND(D4*'2. Assumptions'!B14,0) -> 0 | E8: =ROUND(E4*'2. Assumptions'!B14,0) -> 0 | F8: =ROUND(F4*'2. Assumptions'!C14,0) -> 0 | G8: =ROUND(G4*'2. Assumptions'!C14,0) -> 1 | H8: =ROUND(H4*'2. Assumptions'!C14,0) -> 1 | I8: =ROUND(I4*'2. Assumptions'!C14,0) -> 1 | J8: =ROUND(J4*'2. Assumptions'!D14,0) -> 4 | K8: =ROUND(K4*'2. Assumptions'!D14,0) -> 5 | L8: =ROUND(L4*'2. Assumptions'!D14,0) -> 6 | M8: =ROUND(M4*'2. Assumptions'!D14,0) -> 7
A9: Total buildings under mgmt | B9: =B5*'2. Assumptions'!B18+B6*'2. Assumptions'!B19+B7*'2. Assumptions'!B20+B8*'2. Assumptions'!B21 -> 2 | C9: =C5*'2. Assumptions'!B18+C6*'2. Assumptions'!B19+C7*'2. Assumptions'!B20+C8*'2. Assumptions'!B21 -> 14 | D9: =D5*'2. Assumptions'!B18+D6*'2. Assumptions'!B19+D7*'2. Assumptions'!B20+D8*'2. Assumptions'!B21 -> 31 | E9: =E5*'2. Assumptions'!B18+E6*'2. Assumptions'!B19+E7*'2. Assumptions'!B20+E8*'2. Assumptions'!B21 -> 52 | F9: =F5*'2. Assumptions'!B18+F6*'2. Assumptions'!B19+F7*'2. Assumptions'!B20+F8*'2. Assumptions'!B21 -> 92 | G9: =G5*'2. Assumptions'!B18+G6*'2. Assumptions'!B19+G7*'2. Assumptions'!B20+G8*'2. Assumptions'!B21 -> 151 | H9: =H5*'2. Assumptions'!B18+H6*'2. Assumptions'!B19+H7*'2. Assumptions'!B20+H8*'2. Assumptions'!B21 -> 209 | I9: =I5*'2. Assumptions'!B18+I6*'2. Assumptions'!B19+I7*'2. Assumptions'!B20+I8*'2. Assumptions'!B21 -> 272 | J9: =J5*'2. Assumptions'!B18+J6*'2. Assumptions'!B19+J7*'2. Assumptions'!B20+J8*'2. Assumptions'!B21 -> 436 | K9: =K5*'2. Assumptions'!B18+K6*'2. Assumptions'!B19+K7*'2. Assumptions'!B20+K8*'2. Assumptions'!B21 -> 550 | L9: =L5*'2. Assumptions'!B18+L6*'2. Assumptions'!B19+L7*'2. Assumptions'!B20+L8*'2. Assumptions'!B21 -> 669 | M9: =M5*'2. Assumptions'!B18+M6*'2. Assumptions'!B19+M7*'2. Assumptions'!B20+M8*'2. Assumptions'!B21 -> 798

Sheet 4. Revenue
A1: Revenue — Quarterly (EUR)
A3: Tier revenue | B3: Q3'26 | C3: Q4'26 | D3: Q1'27 | E3: Q2'27 | F3: Q3'27 | G3: Q4'27 | H3: Q1'28 | I3: Q2'28 | J3: Q3'28 | K3: Q4'28 | L3: Q1'29 | M3: Q2'29
A4: Insight (€99 × bldgs × 3mo) | B4: ='3. Customers'!B5*'2. Assumptions'!B18*'2. Assumptions'!B4*3 -> 594 | C4: ='3. Customers'!C5*'2. Assumptions'!B18*'2. Assumptions'!B4*3 -> 1188 | D4: ='3. Customers'!D5*'2. Assumptions'!B18*'2. Assumptions'!B4*3 -> 2376 | E4: ='3. Customers'!E5*'2. Assumptions'!B18*'2. Assumptions'!B4*3 -> 4158 | F4: ='3. Customers'!F5*'2. Assumptions'!B18*'2. Assumptions'!B4*3 -> 5346 | G4: ='3. Customers'!G5*'2. Assumptions'!B18*'2. Assumptions'!B4*3 -> 7128 | H4: ='3. Customers'!H5*'2. Assumptions'!B18*'2. Assumptions'!B4*3 -> 10692 | I4: ='3. Customers'!I5*'2. Assumptions'!B18*'2. Assumptions'!B4*3 -> 14256 | J4: ='3. Customers'!J5*'2. Assumptions'!B18*'2. Assumptions'!B4*3 -> 13662 | K4: ='3. Customers'!K5*'2. Assumptions'!B18*'2. Assumptions'!B4*3 -> 17226 | L4: ='3. Customers'!L5*'2. Assumptions'!B18*'2. Assumptions'!B4*3 -> 20790 | M4: ='3. Customers'!M5*'2. Assumptions'!B18*'2. Assumptions'!B4*3 -> 24948
A5: Monitor (€299 × bldgs × 3mo) | B5: ='3. Customers'!B6*'2. Assumptions'!B19*'2. Assumptions'!B5*3 -> 0 | C5: ='3. Customers'!C6*'2. Assumptions'!B19*'2. Assumptions'!B5*3 -> 8970 | D5: ='3. Customers'!D6*'2. Assumptions'!B19*'2. Assumptions'!B5*3 -> 13455 | E5: ='3. Customers'!E6*'2. Assumptions'!B19*'2. Assumptions'!B5*3 -> 26910 | F5: ='3. Customers'!F6*'2. Assumptions'!B19*'2. Assumptions'!B5*3 -> 44850 | G5: ='3. Customers'!G6*'2. Assumptions'!B19*'2. Assumptions'!B5*3 -> 62790 | H5: ='3. Customers'!H6*'2. Assumptions'!B19*'2. Assumptions'!B5*3 -> 89700 | I5: ='3. Customers'!I6*'2. Assumptions'!B19*'2. Assumptions'!B5*3 -> 121095 | J5: ='3. Customers'!J6*'2. Assumptions'!B19*'2. Assumptions'!B5*3 -> 152490 | K5: ='3. Customers'!K6*'2. Assumptions'!B19*'2. Assumptions'!B5*3 -> 192855 | L5: ='3. Customers'!L6*'2. Assumptions'!B19*'2. Assumptions'!B5*3 -> 237705 | M5: ='3. Customers'!M6*'2. Assumptions'!B19*'2. Assumptions'!B5*3 -> 282555
A6: Copilot (€699 × bldgs × 3mo) | B6: ='3. Customers'!B7*'2. Assumptions'!B20*'2. Assumptions'!B6*3 -> 0 | C6: ='3. Customers'!C7*'2. Assumptions'!B20*'2. Assumptions'!B6*3 -> 0 | D6: ='3. Customers'!D7*'2. Assumptions'!B20*'2. Assumptions'!B6*3 -> 16776 | E6: ='3. Customers'!E7*'2. Assumptions'!B20*'2. Assumptions'!B6*3 -> 16776 | F6: ='3. Customers'!F7*'2. Assumptions'!B20*'2. Assumptions'!B6*3 -> 50328 | G6: ='3. Customers'!G7*'2. Assumptions'!B20*'2. Assumptions'!B6*3 -> 67104 | H6: ='3. Customers'!H7*'2. Assumptions'!B20*'2. Assumptions'!B6*3 -> 100656 | I6: ='3. Customers'!I7*'2. Assumptions'!B20*'2. Assumptions'!B6*3 -> 134208 | J6: ='3. Customers'!J7*'2. Assumptions'!B20*'2. Assumptions'!B6*3 -> 251640 | K6: ='3. Customers'!K7*'2. Assumptions'!B20*'2. Assumptions'!B6*3 -> 318744 | L6: ='3. Customers'!L7*'2. Assumptions'!B20*'2. Assumptions'!B6*3 -> 385848 | M6: ='3. Customers'!M7*'2. Assumptions'!B20*'2. Assumptions'!B6*3 -> 469728
A7: Enterprise (€1500 × bldgs × 3mo) | B7: ='3. Customers'!B8*'2. Assumptions'!B21*'2. Assumptions'!B7*3 -> 0 | C7: ='3. Customers'!C8*'2. Assumptions'!B21*'2. Assumptions'!B7*3 -> 0 | D7: ='3. Customers'!D8*'2. Assumptions'!B21*'2. Assumptions'!B7*3 -> 0 | E7: ='3. Customers'!E8*'2. Assumptions'!B21*'2. Assumptions'!B7*3 -> 0 | F7: ='3. Customers'!F8*'2. Assumptions'!B21*'2. Assumptions'!B7*3 -> 0 | G7: ='3. Customers'!G8*'2. Assumptions'!B21*'2. Assumptions'!B7*3 -> 112500 | H7: ='3. Customers'!H8*'2. Assumptions'!B21*'2. Assumptions'!B7*3 -> 112500 | I7: ='3. Customers'!I8*'2. Assumptions'!B21*'2. Assumptions'!B7*3 -> 112500 | J7: ='3. Customers'!J8*'2. Assumptions'!B21*'2. Assumptions'!B7*3 -> 450000 | K7: ='3. Customers'!K8*'2. Assumptions'!B21*'2. Assumptions'!B7*3 -> 562500 | L7: ='3. Customers'!L8*'2. Assumptions'!B21*'2. Assumptions'!B7*3 -> 675000 | M7: ='3. Customers'!M8*'2. Assumptions'!B21*'2. Assumptions'!B7*3 -> 787500
A9: Total quarterly revenue | B9: =SUM(B4:B7) -> 594 | C9: =SUM(C4:C7) -> 10158 | D9: =SUM(D4:D7) -> 32607 | E9: =SUM(E4:E7) -> 47844 | F9: =SUM(F4:F7) -> 100524 | G9: =SUM(G4:G7) -> 249522 | H9: =SUM(H4:H7) -> 313548 | I9: =SUM(I4:I7) -> 382059 | ... M9: =SUM(M4:M7) -> 1564731
A10: Avg MRR (€) | B10: =B9/3 -> 198 | C10: =C9/3 -> 3386 | D10: =D9/3 -> 10869 | E10: =E9/3 -> 15948 | F10: =F9/3 -> 33508 | G10: =G9/3 -> 83174 | H10: =H9/3 -> 104516 | I10: =I9/3 -> 127353 | ... M10: =M9/3 -> 521577
A11: ARR run rate (end of qtr) | B11: =B10*12 -> 2376 | C11: =C10*12 -> 40632 | D11: =D10*12 -> 130428 | E11: =E10*12 -> 191376 | F11: =F10*12 -> 402096 | G11: =G10*12 -> 998088 | H11: =H10*12 -> 1254192 | I11: =I10*12 -> 1528236 | ... M11: =M10*12 -> 6258924

Sheet 5. Costs
A1: Costs — Quarterly (EUR)
A3: Cost category | B3: Q3'26 | C3: Q4'26 | D3: Q1'27 | E3: Q2'27 | F3: Q3'27 | G3: Q4'27 | H3: Q1'28 | I3: Q2'28 | J3: Q3'28 | K3: Q4'28 | L3: Q1'29 | M3: Q2'29
A4: Microsoft Fabric capacity | B4: ='2. Assumptions'!B40*3 -> 0 | C4: ='2. Assumptions'!B40*3 -> 0 | D4: ='2. Assumptions'!B40*3 -> 0 | E4: ='2. Assumptions'!B40*3 -> 0 | F4: ='2. Assumptions'!B41*3 -> 1200 | G4: ='2. Assumptions'!B41*3 -> 1200 | H4: ='2. Assumptions'!B41*3 -> 1200 | I4: ='2. Assumptions'!B41*3 -> 1200 | J4: ='2. Assumptions'!B41*3 -> 1200 | K4: ='2. Assumptions'!B41*3 -> 1200 | L4: ='2. Assumptions'!B41*3 -> 1200 | M4: ='2. Assumptions'!B41*3 -> 1200
A5: Azure infrastructure | B5: ='2. Assumptions'!B42*3 -> 300 | C5: ='2. Assumptions'!B42*3 -> 300 | D5: ='2. Assumptions'!B42*3 -> 300 | E5: ='2. Assumptions'!B42*3 -> 300 | F5: ='2. Assumptions'!B42*3 -> 300 | G5: ='2. Assumptions'!B42*3 -> 300 | H5: ='2. Assumptions'!B42*3 -> 300 | I5: ='2. Assumptions'!B42*3 -> 300 | J5: ='2. Assumptions'!B42*3 -> 300 | K5: ='2. Assumptions'!B42*3 -> 300 | L5: ='2. Assumptions'!B42*3 -> 300 | M5: ='2. Assumptions'!B42*3 -> 300
A6: Tools | B6: ='2. Assumptions'!B43*3 -> 450 | C6: ='2. Assumptions'!B43*3 -> 450 | D6: ='2. Assumptions'!B43*3 -> 450 | E6: ='2. Assumptions'!B43*3 -> 450 | F6: ='2. Assumptions'!B43*3 -> 450 | G6: ='2. Assumptions'!B43*3 -> 450 | H6: ='2. Assumptions'!B43*3 -> 450 | I6: ='2. Assumptions'!B43*3 -> 450 | J6: ='2. Assumptions'!B43*3 -> 450 | K6: ='2. Assumptions'!B43*3 -> 450 | L6: ='2. Assumptions'!B43*3 -> 450 | M6: ='2. Assumptions'!B43*3 -> 450
A7: Marketing | B7: ='2. Assumptions'!B44*3*1 -> 900 | C7: ='2. Assumptions'!B44*3*1 -> 900 | D7: ='2. Assumptions'!B44*3*1.5 -> 1350 | E7: ='2. Assumptions'!B44*3*1.5 -> 1350 | F7: ='2. Assumptions'!B44*3*2 -> 1800 | G7: ='2. Assumptions'!B44*3*2 -> 1800 | H7: ='2. Assumptions'!B44*3*2.5 -> 2250 | I7: ='2. Assumptions'!B44*3*2.5 -> 2250 | J7: ='2. Assumptions'!B44*3*3 -> 2700 | K7: ='2. Assumptions'!B44*3*3 -> 2700 | L7: ='2. Assumptions'!B44*3*3.5 -> 3150 | M7: ='2. Assumptions'!B44*3*3.5 -> 3150
A8: Admin / domain | B8: ='2. Assumptions'!B45*3 -> 150 | C8: ='2. Assumptions'!B45*3 -> 150 | D8: ='2. Assumptions'!B45*3 -> 150 | E8: ='2. Assumptions'!B45*3 -> 150 | F8: ='2. Assumptions'!B45*3 -> 150 | G8: ='2. Assumptions'!B45*3 -> 150 | H8: ='2. Assumptions'!B45*3 -> 150 | I8: ='2. Assumptions'!B45*3 -> 150 | J8: ='2. Assumptions'!B45*3 -> 150 | K8: ='2. Assumptions'!B45*3 -> 150 | L8: ='2. Assumptions'!B45*3 -> 150 | M8: ='2. Assumptions'!B45*3 -> 150
A9: Salaries (quarterly) | B9: 0 | C9: 0 | D9: 0 | E9: 11250 | F9: 25000 | G9: 36250 | H9: 36250 | I9: 55000 | J9: 70000 | K9: 70000 | L9: 70000 | M9: 70000
A10: Total quarterly cost | B10: =SUM(B4:B9) -> 1800 | C10: =SUM(C4:C9) -> 1800 | D10: =SUM(D4:D9) -> 2250 | E10: =SUM(E4:E9) -> 13500 | F10: =SUM(F4:F9) -> 28900 | G10: =SUM(G4:G9) -> 40150 | H10: =SUM(H4:H9) -> 40600 | I10: =SUM(I4:I9) -> 59350 | ... M10: =SUM(M4:M9) -> 75250

Sheet 6. P&L Summary
A1: P&L Summary — 3-Year View
A3: Metric | B3: Year 1 (Q3'26-Q2'27) | C3: Year 2 (Q3'27-Q2'28) | D3: Year 3 (Q3'28-Q2'29) | E3: Year 3 EOY | F3: 3-Yr Total
A5: New customers added | B5: =SUM('2. Assumptions'!B25:B28) -> 14 | C5: =SUM('2. Assumptions'!B29:B32) -> 48 | D5: =SUM('2. Assumptions'!B33:B36) -> 93 | F5: =SUM(B5:D5) -> 155
A6: Cumulative customers at year-end | B6: ='2. Assumptions'!C28 -> 14 | C6: ='2. Assumptions'!C32 -> 59 | D6: ='2. Assumptions'!C36 -> 141
A7: Buildings under mgmt at year-end | B7: ='3. Customers'!E9 -> 52 | C7: ='3. Customers'!I9 -> 272 | D7: ='3. Customers'!M9 -> 798
A9: REVENUE
A10: Annual revenue | B10: =SUM('4. Revenue'!B9:E9) -> 91203 | C10: =SUM('4. Revenue'!F9:I9) -> 1045653 | D10: =SUM('4. Revenue'!J9:M9) -> 4843191 | F10: =SUM(B10:D10) -> 5980047
A11: ARR at year-end | B11: ='4. Revenue'!E11 -> 191376 | C11: ='4. Revenue'!I11 -> 1528236 | D11: ='4. Revenue'!M11 -> 6258924
A13: COSTS
A14: Annual costs | B14: =SUM('5. Costs'!B10:E10) -> 19350 | C14: =SUM('5. Costs'!F10:I10) -> 169000 | D14: =SUM('5. Costs'!J10:M10) -> 300100 | F14: =SUM(B14:D14) -> 488450
A15: NET INCOME | B15: =B10-B14 -> 71853 | C15: =C10-C14 -> 876653 | D15: =D10-D14 -> 4543091 | F15: =SUM(B15:D15) -> 5491597
A17: Cumulative cash position | B17: =B15 -> 71853 | C17: =B17+C15 -> 948506 | D17: =C17+D15 -> 5491597
A19: KEY METRICS
A20: Year 3 ARR (forward-looking) | E20: =D11 -> 6258924 | F20: =B10+C10+D10 -> 5980047
A22: Gross margin % | B22: =(B10-B14)/B10 -> 0.78783593 | C22: =(C10-C14)/C10 -> 0.83837851 | D22: =(D10-D14)/D10 -> 0.93803672
A23: Avg revenue per customer (annual) | B23: =IFERROR(B10/B6,0) -> 6514.5 | C23: =IFERROR(C10/C6,0) -> 17722.932 | D23: =IFERROR(D10/D6,0) -> 34348.872

Sheet 7. Microsoft Ask
A1: Microsoft for Startups — Credit Utilization Plan
A3: Resource | B3: Monthly cost (€) | C3: 12-month total (€) | D3: Strategic value | E3: Usage timing
A4: Microsoft Fabric F8 capacity | B4: 1800 | C4: =B4*12 -> 21600 | D4: Production pipeline (unblocks F4 trial throttle) | E4: Months 1-12
A5: Power BI Premium per Capacity | B5: 400 | C5: =B5*12 -> 4800 | D5: Embedded analytics for SaaS customers | E5: Months 1-12
A6: Azure Container Apps (web app backend) | B6: 80 | C6: =B6*12 -> 960 | D6: FastAPI deployment | E6: Months 1-12
A7: Azure Static Web Apps (frontend) | B7: 20 | C7: =B7*12 -> 240 | D7: Next.js hosting | E7: Months 1-12
A8: Azure PostgreSQL Flexible (DB) | B8: 30 | C8: =B8*12 -> 360 | D8: User/subscription DB | E8: Months 1-12
A9: Azure OpenAI credits | B9: 600 | C9: =B9*12 -> 7200 | D9: AI recommendation engine (Phase 2, months 6-12) | E9: Months 6-12 (avg)
A10: Application Insights monitoring | B10: 30 | C10: =B10*12 -> 360 | D10: Telemetry | E10: Months 1-12
A11: Microsoft Entra ID + Azure AD B2C | B11: 20 | C11: =B11*12 -> 240 | D11: Customer authentication | E11: Months 1-12
A12: TOTAL | B12: =SUM(B4:B11) -> 2980 | C12: =SUM(C4:C11) -> 35760
A14: EUR to USD (avg 2026) | B14: 1.08
A15: 12-month value in USD | C15: =C12*B14 -> 38620.8
A17: TIER MAPPING
A18: Microsoft Startups Tier 1 (~$1k) | B18: Insufficient — covers basic Azure only
A19: Microsoft Startups Tier 2 (~$25k) | B19: Covers Year 1 essentials — Fabric + Power BI + Azure
A20: Microsoft Startups Tier 3 (~$150k) | B20: Covers Years 1-3 fully, includes Azure OpenAI scaling
A22: WHY THIS MATTERS
A23: • Without Microsoft Startups support, current Fabric F4 trial cannot sustain production workloads.
A24: • Trial ends 2026-06-12; without Tier 2 acceptance, project hits hard infrastructure ceiling.
A25: • Microsoft Startups credits replace ~€40-60k Year 1 infrastructure expense — direct runway extension.
A26: • Tier 2 acceptance demonstrates Microsoft endorsement, accelerating enterprise sales cycle.
A27: • Path to Tier 3: 3-6 months post-acceptance with traction proof (customers, MRR).
