Workbook

Sheet 01_README
A2: Dynamic tariff — customer & supplier unit economics
A4: PURPOSE: decide whether a customer segment is worth acquiring onto the dynamic tariff, and what the supplier earns from them per year.
A6: HOW TO USE
A7: 1. Only ever type in the YELLOW cells on 02_Inputs. Everything else is formulas.
A8: 2. 03_Model computes volumes, the customer bill and the supplier P&L.
A9: 3. 04_Sensitivity shows what the answer actually hinges on. Read this before quoting a number.
A10: 4. 05_SQL_Actuals holds the real pipeline output, so the model can be reconciled against data.
A11: 5. 07_Checks tries to break the model. If anything says CHECK, do not present the model.
A13: THE ONE INSIGHT THIS MODEL EXISTS TO PROTECT YOU FROM
A14: Only the commodity component of a German electricity bill follows the spot price. Grid fees, levies, taxes and VAT do not. So a customer who shifts 30% of consumption into the cheapest quarter-hours does NOT save 30%. The model shows the true share on 03_Model. Over-promised savings are the single biggest churn driver in this segment.
A16: ASSUMPTIONS ARE NOT FACTS
A17: Every input on 02_Inputs has a source note. Where the source says ASSUMPTION, the number is a judgement, and the sensitivity tab tells you how much it matters. Never present an output without naming the two inputs it is most sensitive to.
... A20: Data: synthetic, generated by 01_generate_data.py. Prices modelled on German day-ahead shape.

Sheet 02_Inputs
A1: INPUTS — the only cells you may type in (yellow)
A2: Driver | B2: Value | C2: Unit | D2: Source / note
A3: — CUSTOMER PHYSICAL —
A4: Annual consumption | B4: 9500 | C4: kWh/yr | D4: PV+battery+heat-pump household: 2.5-3.5k base + 3.5-6k heat pump
A5: PV capacity | B5: 10 | C5: kWp | D5: Typical German residential rooftop 8–12 kWp
A6: Specific yield | B6: 980 | C6: kWh/kWp/yr | D6: German range 950–1,100 (assumption, location dependent)
A7: Eigenverbrauchsquote, PV only | B7: 0.3 | C7: share | D7: Share of PV GENERATION used on site, no storage: 25–35%
A8: Eigenverbrauchsquote uplift, battery | B8: 0.28 | C8: share | D8: Battery lifts on-site use of generation to ~55–65%
A9: Autarkiegrad cap, PV only | B9: 0.3 | C9: share | D9: Share of LOAD that PV can physically cover, no storage: 25–35%
A10: Autarkiegrad uplift, battery | B10: 0.3 | C10: share | D10: With storage self-sufficiency reaches ~55–70%. PV does not generate at night — this cap is the physics.
A11: Battery usable capacity | B11: 10 | C11: kWh | D11: Usable, i.e. after depth-of-discharge
A12: Controllable capacity for VPP | B12: 8 | C12: kW | D12: 0.5C on a 10 kWh battery (5 kW) + 3 kW heat pump
A13: — MARKET & PRICE STACK —
A14: Average day-ahead spot | B14: 8.81 | C14: ct/kWh | D14: Period mean from 05_SQL_Actuals (measured, not assumed)
A15: Realised/average price ratio | B15: 0.987 | C15: x | D15: From the backtest: <1 means shifting works (measured)
A16: Supplier markup on spot | B16: 1.8 | C16: ct/kWh | D16: Commercial decision — the main lever you own
A17: Base fee, dynamic tariff | B17: 12.99 | C17: EUR/month | D17: Competitive range: Ostrom 6, Tibber 5.99, aWATTar 4.58
A18: HEMS software fee | B18: 9.9 | C18: EUR/month | D18: Heartbeat-style software subscription (ASSUMPTION)
A19: Grid fee (Netzentgelt) | B19: 9.26 | C19: ct/kWh | D19: German household average 2026, −15% y/y on state subsidy
A20: Levies + taxes | B20: 12.61 | C20: ct/kWh | D20: Stromsteuer 2.05 + KWKG 0.45 + §19 StromNEV 1.56 + offshore 0.94 + concession
A21: VAT | B21: 0.19 | C21: share | D21: German statutory rate
A22: Fixed tariff energy component | B22: 15.4 | C22: ct/kWh | D22: The counterfactual — procurement+sales+margin, ~41% of 37.2 ct
A23: — SUPPLIER COMMERCIALS —
A24: Customer acquisition cost | B24: 420 | C24: EUR | D24: Blended CAC (ASSUMPTION — the least reliable input here)
A25: Service + billing cost | B25: 28 | C25: EUR/yr | D25: Support, invoicing, MaKo clearing per customer (ASSUMPTION)
A26: Imbalance cost | B26: 0.35 | C26: ct/kWh | D26: Ausgleichsenergie from portfolio forecast error (ASSUMPTION)
A27: Flexibility revenue | B27: 18 | C27: EUR/kW/yr | D27: MEASURED FLOOR: the backtest earned EUR ~57/battery/yr from spot arbitrage alone (EUR 282 / 20 batteries / 90d). Balancing-market participation could multiply it; 18/kW/yr keeps the case honest.
A28: Annual churn | B28: 0.12 | C28: share | D28: 12%/yr → 8.3 year expected life (ASSUMPTION)
A30: Yellow = input. Any other colour = formula. If you find yourself typing a number outside this block, stop and add it here instead.

Sheet 03_Model
A1: 1 · VOLUMES
A2: PV generation | B2: ='02_Inputs'!$B$5*'02_Inputs'!$B$6 | C2: kWh/yr | D2: capacity × specific yield
A3: Eigenverbrauchsquote | B3: ='02_Inputs'!$B$7+IF('02_Inputs'!$B$11>0,'02_Inputs'!$B$8,0) | C3: share | D3: share of PV GENERATION used on site
A4: Autarkiegrad cap | B4: ='02_Inputs'!$B$9+IF('02_Inputs'!$B$11>0,'02_Inputs'!$B$10,0) | C4: share | D4: share of LOAD that PV can physically cover
A5: Self-consumed PV | B5: =MIN('03_Model'!$B$2*'03_Model'!$B$3,'02_Inputs'!$B$4*'03_Model'!$B$4) | C5: kWh/yr | D5: TWO binding constraints: how much generation you can use, AND how much load solar can physically cover. Capping only by consumption gives 100% self-sufficiency, which is impossible — PV does not generate at night.
A6: Grid import | B6: ='02_Inputs'!$B$4-'03_Model'!$B$5 | C6: kWh/yr | D6: the volume that is actually billed
A7: PV export | B7: =MAX('03_Model'!$B$2-'03_Model'!$B$5,0) | C7: kWh/yr | D7: surplus — feed-in or Direktvermarktung
A9: 2 · PRICE STACK (this is where the 40% insight lives)
A10: Customer effective spot | B10: ='02_Inputs'!$B$14*'02_Inputs'!$B$15 | C10: ct/kWh | D10: average spot × realised/average ratio — NOT the simple average
A11: Dynamic energy component | B11: ='03_Model'!$B$10+'02_Inputs'!$B$16 | C11: ct/kWh | D11: spot + markup
A12: Non-commodity component | B12: ='02_Inputs'!$B$19+'02_Inputs'!$B$20 | C12: ct/kWh | D12: grid + levies: does NOT follow the market
A13: Dynamic price, gross | B13: =('03_Model'!$B$11+'03_Model'!$B$12)*(1+'02_Inputs'!$B$21) | C13: ct/kWh | D13: incl. VAT
A14: Fixed price, gross | B14: =('02_Inputs'!$B$22+'03_Model'!$B$12)*(1+'02_Inputs'!$B$21) | C14: ct/kWh | D14: the counterfactual
A15: Commodity share of net price | B15: ='03_Model'!$B$11/('03_Model'!$B$11+'03_Model'!$B$12) | C15: share | D15: THE NUMBER. Only this share of the bill can move with the market.
A16: Max theoretical saving from a 30% shift | B16: =0.3*'03_Model'!$B$15 | C16: share | D16: why '30% cheaper' is never true
A18: 3 · CUSTOMER BILL
A19: Annual bill — dynamic | B19: ='03_Model'!$B$6*'03_Model'!$B$13/100+'02_Inputs'!$B$17*12 | C19: EUR/yr
A20: Annual bill — fixed | B20: ='03_Model'!$B$6*'03_Model'!$B$14/100+'02_Inputs'!$B$17*12 | C20: EUR/yr | D20: same base fee, so the comparison is on energy only
A21: Saving vs fixed | B21: ='03_Model'!$B$20-'03_Model'!$B$19 | C21: EUR/yr
A22: Saving vs fixed, % | B22: ='03_Model'!$B$21/'03_Model'!$B$20 | C22: share | D22: compare against the max theoretical above
A24: 4 · SUPPLIER P&L PER CUSTOMER
A25: Energy margin | B25: ='03_Model'!$B$6*'02_Inputs'!$B$16/100 | C25: EUR/yr | D25: markup × billed volume
A26: Base fee revenue | B26: ='02_Inputs'!$B$17*12 | C26: EUR/yr
A27: Software revenue | B27: ='02_Inputs'!$B$18*12 | C27: EUR/yr | D27: recurring, high margin
A28: Flexibility revenue | B28: ='02_Inputs'!$B$27*'02_Inputs'!$B$12 | C28: EUR/yr | D28: the VPP leg — scales with controllable kW, not kWh
A29: Total revenue | B29: =SUM('03_Model'!$B$25,'03_Model'!$B$26,'03_Model'!$B$27,'03_Model'!$B$28) | C29: EUR/yr
A30: Imbalance cost | B30: =-'03_Model'!$B$6*'02_Inputs'!$B$26/100 | C30: EUR/yr | D30: forecast error, borne by the BKV
A31: Service + billing cost | B31: =-'02_Inputs'!$B$25 | C31: EUR/yr
A32: Total cost | B32: =SUM('03_Model'!$B$30,'03_Model'!$B$31) | C32: EUR/yr
A33: Gross margin | B33: ='03_Model'!$B$29+'03_Model'!$B$32 | C33: EUR/yr | D33: the number the business is steered by
A35: 5 · RETURN ON ACQUISITION
A36: CAC payback | B36: ='02_Inputs'!$B$24/('03_Model'!$B$33/12) | C36: months | D36: < 18 months is healthy
A37: Expected customer life | B37: =1/'02_Inputs'!$B$28 | C37: years | D37: 1 / annual churn
A38: Lifetime value | B38: ='03_Model'!$B$33*'03_Model'!$B$37 | C38: EUR | D38: undiscounted — a real model would NPV this
A39: LTV / CAC | B39: ='03_Model'!$B$38/'02_Inputs'!$B$24 | C39: x | D39: > 3.0 is the usual bar

Sheet 04_Sensitivity
A1: SENSITIVITY — Google Sheets has no Data Table, so we build a formula grid
A2: Each cell recomputes the whole chain from first principles. That is why no number may be hardcoded upstream.
A4: GRID 1 · Supplier LTV/CAC
A5: rows = markup (ct/kWh) cols = annual churn
B6: 0.06 | C6: 0.09 | D6: 0.12 | E6: 0.15 | F6: 0.2
A7: 0.8 | B7: =(('03_Model'!$B$6*$A7/100+'02_Inputs'!$B$17*12+'02_Inputs'!$B$18*12+'02_Inputs'!$B$27*'02_Inputs'!$B$12-'03_Model'!$B$6*'02_Inputs'!$B$26/100-'02_Inputs'!$B$25)*(1/B$6))/'02_Inputs'!$B$24 | C7: =(('03_Model'!$B$6*$A7/100+'02_Inputs'!$B$17*12+'02_Inputs'!$B$18*12+'02_Inputs'!$B$27*'02_Inputs'!$B$12-'03_Model'!$B$6*'02_Inputs'!$B$26/100-'02_Inputs'!$B$25)*(1/C$6))/'02_Inputs'!$B$24 | D7: =(('03_Model'!$B$6*$A7/100+'02_Inputs'!$B$17*12+'02_Inputs'!$B$18*12+'02_Inputs'!$B$27*'02_Inputs'!$B$12-'03_Model'!$B$6*'02_Inputs'!$B$26/100-'02_Inputs'!$B$25)*(1/D$6))/'02_Inputs'!$B$24 | E7: =(('03_Model'!$B$6*$A7/100+'02_Inputs'!$B$17*12+'02_Inputs'!$B$18*12+'02_Inputs'!$B$27*'02_Inputs'!$B$12-'03_Model'!$B$6*'02_Inputs'!$B$26/100-'02_Inputs'!$B$25)*(1/E$6))/'02_Inputs'!$B$24 | F7: =(('03_Model'!$B$6*$A7/100+'02_Inputs'!$B$17*12+'02_Inputs'!$B$18*12+'02_Inputs'!$B$27*'02_Inputs'!$B$12-'03_Model'!$B$6*'02_Inputs'!$B$26/100-'02_Inputs'!$B$25)*(1/F$6))/'02_Inputs'!$B$24
A8: 1.2 | B8: =(('03_Model'!$B$6*$A8/100+'02_Inputs'!$B$17*12+'02_Inputs'!$B$18*12+'02_Inputs'!$B$27*'02_Inputs'!$B$12-'03_Model'!$B$6*'02_Inputs'!$B$26/100-'02_Inputs'!$B$25)*(1/B$6))/'02_Inputs'!$B$24 | C8: =(('03_Model'!$B$6*$A8/100+'02_Inputs'!$B$17*12+'02_Inputs'!$B$18*12+'02_Inputs'!$B$27*'02_Inputs'!$B$12-'03_Model'!$B$6*'02_Inputs'!$B$26/100-'02_Inputs'!$B$25)*(1/C$6))/'02_Inputs'!$B$24 | D8: =(('03_Model'!$B$6*$A8/100+'02_Inputs'!$B$17*12+'02_Inputs'!$B$18*12+'02_Inputs'!$B$27*'02_Inputs'!$B$12-'03_Model'!$B$6*'02_Inputs'!$B$26/100-'02_Inputs'!$B$25)*(1/D$6))/'02_Inputs'!$B$24 | E8: =(('03_Model'!$B$6*$A8/100+'02_Inputs'!$B$17*12+'02_Inputs'!$B$18*12+'02_Inputs'!$B$27*'02_Inputs'!$B$12-'03_Model'!$B$6*'02_Inputs'!$B$26/100-'02_Inputs'!$B$25)*(1/E$6))/'02_Inputs'!$B$24 | F8: =(('03_Model'!$B$6*$A8/100+'02_Inputs'!$B$17*12+'02_Inputs'!$B$18*12+'02_Inputs'!$B$27*'02_Inputs'!$B$12-'03_Model'!$B$6*'02_Inputs'!$B$26/100-'02_Inputs'!$B$25)*(1/F$6))/'02_Inputs'!$B$24
A9: 1.8 | B9: =(('03_Model'!$B$6*$A9/100+'02_Inputs'!$B$17*12+'02_Inputs'!$B$18*12+'02_Inputs'!$B$27*'02_Inputs'!$B$12-'03_Model'!$B$6*'02_Inputs'!$B$26/100-'02_Inputs'!$B$25)*(1/B$6))/'02_Inputs'!$B$24 | C9: =(('03_Model'!$B$6*$A9/100+'02_Inputs'!$B$17*12+'02_Inputs'!$B$18*12+'02_Inputs'!$B$27*'02_Inputs'!$B$12-'03_Model'!$B$6*'02_Inputs'!$B$26/100-'02_Inputs'!$B$25)*(1/C$6))/'02_Inputs'!$B$24 | D9: =(('03_Model'!$B$6*$A9/100+'02_Inputs'!$B$17*12+'02_Inputs'!$B$18*12+'02_Inputs'!$B$27*'02_Inputs'!$B$12-'03_Model'!$B$6*'02_Inputs'!$B$26/100-'02_Inputs'!$B$25)*(1/D$6))/'02_Inputs'!$B$24 | E9: =(('03_Model'!$B$6*$A9/100+'02_Inputs'!$B$17*12+'02_Inputs'!$B$18*12+'02_Inputs'!$B$27*'02_Inputs'!$B$12-'03_Model'!$B$6*'02_Inputs'!$B$26/100-'02_Inputs'!$B$25)*(1/E$6))/'02_Inputs'!$B$24 | F9: =(('03_Model'!$B$6*$A9/100+'02_Inputs'!$B$17*12+'02_Inputs'!$B$18*12+'02_Inputs'!$B$27*'02_Inputs'!$B$12-'03_Model'!$B$6*'02_Inputs'!$B$26/100-'02_Inputs'!$B$25)*(1/F$6))/'02_Inputs'!$B$24
A10: 2.4 | B10: =(('03_Model'!$B$6*$A10/100+'02_Inputs'!$B$17*12+'02_Inputs'!$B$18*12+'02_Inputs'!$B$27*'02_Inputs'!$B$12-'03_Model'!$B$6*'02_Inputs'!$B$26/100-'02_Inputs'!$B$25)*(1/B$6))/'02_Inputs'!$B$24 | C10: =(('03_Model'!$B$6*$A10/100+'02_Inputs'!$B$17*12+'02_Inputs'!$B$18*12+'02_Inputs'!$B$27*'02_Inputs'!$B$12-'03_Model'!$B$6*'02_Inputs'!$B$26/100-'02_Inputs'!$B$25)*(1/C$6))/'02_Inputs'!$B$24 | D10: =(('03_Model'!$B$6*$A10/100+'02_Inputs'!$B$17*12+'02_Inputs'!$B$18*12+'02_Inputs'!$B$27*'02_Inputs'!$B$12-'03_Model'!$B$6*'02_Inputs'!$B$26/100-'02_Inputs'!$B$25)*(1/D$6))/'02_Inputs'!$B$24 | E10: =(('03_Model'!$B$6*$A10/100+'02_Inputs'!$B$17*12+'02_Inputs'!$B$18*12+'02_Inputs'!$B$27*'02_Inputs'!$B$12-'03_Model'!$B$6*'02_Inputs'!$B$26/100-'02_Inputs'!$B$25)*(1/E$6))/'02_Inputs'!$B$24 | F10: =(('03_Model'!$B$6*$A10/100+'02_Inputs'!$B$17*12+'02_Inputs'!$B$18*12+'02_Inputs'!$B$27*'02_Inputs'!$B$12-'03_Model'!$B$6*'02_Inputs'!$B$26/100-'02_Inputs'!$B$25)*(1/F$6))/'02_Inputs'!$B$24
A11: 3 | B11: =(('03_Model'!$B$6*$A11/100+'02_Inputs'!$B$17*12+'02_Inputs'!$B$18*12+'02_Inputs'!$B$27*'02_Inputs'!$B$12-'03_Model'!$B$6*'02_Inputs'!$B$26/100-'02_Inputs'!$B$25)*(1/B$6))/'02_Inputs'!$B$24 | C11: =(('03_Model'!$B$6*$A11/100+'02_Inputs'!$B$17*12+'02_Inputs'!$B$18*12+'02_Inputs'!$B$27*'02_Inputs'!$B$12-'03_Model'!$B$6*'02_Inputs'!$B$26/100-'02_Inputs'!$B$25)*(1/C$6))/'02_Inputs'!$B$24 | D11: =(('03_Model'!$B$6*$A11/100+'02_Inputs'!$B$17*12+'02_Inputs'!$B$18*12+'02_Inputs'!$B$27*'02_Inputs'!$B$12-'03_Model'!$B$6*'02_Inputs'!$B$26/100-'02_Inputs'!$B$25)*(1/D$6))/'02_Inputs'!$B$24 | E11: =(('03_Model'!$B$6*$A11/100+'02_Inputs'!$B$17*12+'02_Inputs'!$B$18*12+'02_Inputs'!$B$27*'02_Inputs'!$B$12-'03_Model'!$B$6*'02_Inputs'!$B$26/100-'02_Inputs'!$B$25)*(1/E$6))/'02_Inputs'!$B$24 | F11: =(('03_Model'!$B$6*$A11/100+'02_Inputs'!$B$17*12+'02_Inputs'!$B$18*12+'02_Inputs'!$B$27*'02_Inputs'!$B$12-'03_Model'!$B$6*'02_Inputs'!$B$26/100-'02_Inputs'!$B$25)*(1/F$6))/'02_Inputs'!$B$24
A12: 3.6 | B12: =(('03_Model'!$B$6*$A12/100+'02_Inputs'!$B$17*12+'02_Inputs'!$B$18*12+'02_Inputs'!$B$27*'02_Inputs'!$B$12-'03_Model'!$B$6*'02_Inputs'!$B$26/100-'02_Inputs'!$B$25)*(1/B$6))/'02_Inputs'!$B$24 | C12: =(('03_Model'!$B$6*$A12/100+'02_Inputs'!$B$17*12+'02_Inputs'!$B$18*12+'02_Inputs'!$B$27*'02_Inputs'!$B$12-'03_Model'!$B$6*'02_Inputs'!$B$26/100-'02_Inputs'!$B$25)*(1/C$6))/'02_Inputs'!$B$24 | D12: =(('03_Model'!$B$6*$A12/100+'02_Inputs'!$B$17*12+'02_Inputs'!$B$18*12+'02_Inputs'!$B$27*'02_Inputs'!$B$12-'03_Model'!$B$6*'02_Inputs'!$B$26/100-'02_Inputs'!$B$25)*(1/D$6))/'02_Inputs'!$B$24 | E12: =(('03_Model'!$B$6*$A12/100+'02_Inputs'!$B$17*12+'02_Inputs'!$B$18*12+'02_Inputs'!$B$27*'02_Inputs'!$B$12-'03_Model'!$B$6*'02_Inputs'!$B$26/100-'02_Inputs'!$B$25)*(1/E$6))/'02_Inputs'!$B$24 | F12: =(('03_Model'!$B$6*$A12/100+'02_Inputs'!$B$17*12+'02_Inputs'!$B$18*12+'02_Inputs'!$B$27*'02_Inputs'!$B$12-'03_Model'!$B$6*'02_Inputs'!$B$26/100-'02_Inputs'!$B$25)*(1/F$6))/'02_Inputs'!$B$24
A15: GRID 2 · Customer saving vs fixed (%)
A16: rows = average spot (ct/kWh) cols = realised/average ratio
B17: 0.9 | C17: 0.95 | D17: 1 | E17: 1.05 | F17: 1.1
A18: 4 | B18: =1-('03_Model'!$B$6*(($A18*B$17+'02_Inputs'!$B$16)+'03_Model'!$B$12)*(1+'02_Inputs'!$B$21)/100+'02_Inputs'!$B$17*12)/('03_Model'!$B$6*(('02_Inputs'!$B$22)+'03_Model'!$B$12)*(1+'02_Inputs'!$B$21)/100+'02_Inputs'!$B$17*12) | C18: =1-('03_Model'!$B$6*(($A18*C$17+'02_Inputs'!$B$16)+'03_Model'!$B$12)*(1+'02_Inputs'!$B$21)/100+'02_Inputs'!$B$17*12)/('03_Model'!$B$6*(('02_Inputs'!$B$22)+'03_Model'!$B$12)*(1+'02_Inputs'!$B$21)/100+'02_Inputs'!$B$17*12) | D18: =1-('03_Model'!$B$6*(($A18*D$17+'02_Inputs'!$B$16)+'03_Model'!$B$12)*(1+'02_Inputs'!$B$21)/100+'02_Inputs'!$B$17*12)/('03_Model'!$B$6*(('02_Inputs'!$B$22)+'03_Model'!$B$12)*(1+'02_Inputs'!$B$21)/100+'02_Inputs'!$B$17*12) | E18: =1-('03_Model'!$B$6*(($A18*E$17+'02_Inputs'!$B$16)+'03_Model'!$B$12)*(1+'02_Inputs'!$B$21)/100+'02_Inputs'!$B$17*12)/('03_Model'!$B$6*(('02_Inputs'!$B$22)+'03_Model'!$B$12)*(1+'02_Inputs'!$B$21)/100+'02_Inputs'!$B$17*12) | F18: =1-('03_Model'!$B$6*(($A18*F$17+'02_Inputs'!$B$16)+'03_Model'!$B$12)*(1+'02_Inputs'!$B$21)/100+'02_Inputs'!$B$17*12)/('03_Model'!$B$6*(('02_Inputs'!$B$22)+'03_Model'!$B$12)*(1+'02_Inputs'!$B$21)/100+'02_Inputs'!$B$17*12)
A19: 6 | B19: =1-('03_Model'!$B$6*(($A19*B$17+'02_Inputs'!$B$16)+'03_Model'!$B$12)*(1+'02_Inputs'!$B$21)/100+'02_Inputs'!$B$17*12)/('03_Model'!$B$6*(('02_Inputs'!$B$22)+'03_Model'!$B$12)*(1+'02_Inputs'!$B$21)/100+'02_Inputs'!$B$17*12) | C19: =1-('03_Model'!$B$6*(($A19*C$17+'02_Inputs'!$B$16)+'03_Model'!$B$12)*(1+'02_Inputs'!$B$21)/100+'02_Inputs'!$B$17*12)/('03_Model'!$B$6*(('02_Inputs'!$B$22)+'03_Model'!$B$12)*(1+'02_Inputs'!$B$21)/100+'02_Inputs'!$B$17*12) | D19: =1-('03_Model'!$B$6*(($A19*D$17+'02_Inputs'!$B$16)+'03_Model'!$B$12)*(1+'02_Inputs'!$B$21)/100+'02_Inputs'!$B$17*12)/('03_Model'!$B$6*(('02_Inputs'!$B$22)+'03_Model'!$B$12)*(1+'02_Inputs'!$B$21)/100+'02_Inputs'!$B$17*12) | E19: =1-('03_Model'!$B$6*(($A19*E$17+'02_Inputs'!$B$16)+'03_Model'!$B$12)*(1+'02_Inputs'!$B$21)/100+'02_Inputs'!$B$17*12)/('03_Model'!$B$6*(('02_Inputs'!$B$22)+'03_Model'!$B$12)*(1+'02_Inputs'!$B$21)/100+'02_Inputs'!$B$17*12) | F19: =1-('03_Model'!$B$6*(($A19*F$17+'02_Inputs'!$B$16)+'03_Model'!$B$12)*(1+'02_Inputs'!$B$21)/100+'02_Inputs'!$B$17*12)/('03_Model'!$B$6*(('02_Inputs'!$B$22)+'03_Model'!$B$12)*(1+'02_Inputs'!$B$21)/100+'02_Inputs'!$B$17*12)
A20: 8.81 | B20: =1-('03_Model'!$B$6*(($A20*B$17+'02_Inputs'!$B$16)+'03_Model'!$B$12)*(1+'02_Inputs'!$B$21)/100+'02_Inputs'!$B$17*12)/('03_Model'!$B$6*(('02_Inputs'!$B$22)+'03_Model'!$B$12)*(1+'02_Inputs'!$B$21)/100+'02_Inputs'!$B$17*12) | C20: =1-('03_Model'!$B$6*(($A20*C$17+'02_Inputs'!$B$16)+'03_Model'!$B$12)*(1+'02_Inputs'!$B$21)/100+'02_Inputs'!$B$17*12)/('03_Model'!$B$6*(('02_Inputs'!$B$22)+'03_Model'!$B$12)*(1+'02_Inputs'!$B$21)/100+'02_Inputs'!$B$17*12) | D20: =1-('03_Model'!$B$6*(($A20*D$17+'02_Inputs'!$B$16)+'03_Model'!$B$12)*(1+'02_Inputs'!$B$21)/100+'02_Inputs'!$B$17*12)/('03_Model'!$B$6*(('02_Inputs'!$B$22)+'03_Model'!$B$12)*(1+'02_Inputs'!$B$21)/100+'02_Inputs'!$B$17*12) | E20: =1-('03_Model'!$B$6*(($A20*E$17+'02_Inputs'!$B$16)+'03_Model'!$B$12)*(1+'02_Inputs'!$B$21)/100+'02_Inputs'!$B$17*12)/('03_Model'!$B$6*(('02_Inputs'!$B$22)+'03_Model'!$B$12)*(1+'02_Inputs'!$B$21)/100+'02_Inputs'!$B$17*12) | F20: =1-('03_Model'!$B$6*(($A20*F$17+'02_Inputs'!$B$16)+'03_Model'!$B$12)*(1+'02_Inputs'!$B$21)/100+'02_Inputs'!$B$17*12)/('03_Model'!$B$6*(('02_Inputs'!$B$22)+'03_Model'!$B$12)*(1+'02_Inputs'!$B$21)/100+'02_Inputs'!$B$17*12)
A21: 11 | B21: =1-('03_Model'!$B$6*(($A21*B$17+'02_Inputs'!$B$16)+'03_Model'!$B$12)*(1+'02_Inputs'!$B$21)/100+'02_Inputs'!$B$17*12)/('03_Model'!$B$6*(('02_Inputs'!$B$22)+'03_Model'!$B$12)*(1+'02_Inputs'!$B$21)/100+'02_Inputs'!$B$17*12) | C21: =1-('03_Model'!$B$6*(($A21*C$17+'02_Inputs'!$B$16)+'03_Model'!$B$12)*(1+'02_Inputs'!$B$21)/100+'02_Inputs'!$B$17*12)/('03_Model'!$B$6*(('02_Inputs'!$B$22)+'03_Model'!$B$12)*(1+'02_Inputs'!$B$21)/100+'02_Inputs'!$B$17*12) | D21: =1-('03_Model'!$B$6*(($A21*D$17+'02_Inputs'!$B$16)+'03_Model'!$B$12)*(1+'02_Inputs'!$B$21)/100+'02_Inputs'!$B$17*12)/('03_Model'!$B$6*(('02_Inputs'!$B$22)+'03_Model'!$B$12)*(1+'02_Inputs'!$B$21)/100+'02_Inputs'!$B$17*12) | E21: =1-('03_Model'!$B$6*(($A21*E$17+'02_Inputs'!$B$16)+'03_Model'!$B$12)*(1+'02_Inputs'!$B$21)/100+'02_Inputs'!$B$17*12)/('03_Model'!$B$6*(('02_Inputs'!$B$22)+'03_Model'!$B$12)*(1+'02_Inputs'!$B$21)/100+'02_Inputs'!$B$17*12) | F21: =1-('03_Model'!$B$6*(($A21*F$17+'02_Inputs'!$B$16)+'03_Model'!$B$12)*(1+'02_Inputs'!$B$21)/100+'02_Inputs'!$B$17*12)/('03_Model'!$B$6*(('02_Inputs'!$B$22)+'03_Model'!$B$12)*(1+'02_Inputs'!$B$21)/100+'02_Inputs'!$B$17*12)
A22: 13 | B22: =1-('03_Model'!$B$6*(($A22*B$17+'02_Inputs'!$B$16)+'03_Model'!$B$12)*(1+'02_Inputs'!$B$21)/100+'02_Inputs'!$B$17*12)/('03_Model'!$B$6*(('02_Inputs'!$B$22)+'03_Model'!$B$12)*(1+'02_Inputs'!$B$21)/100+'02_Inputs'!$B$17*12) | C22: =1-('03_Model'!$B$6*(($A22*C$17+'02_Inputs'!$B$16)+'03_Model'!$B$12)*(1+'02_Inputs'!$B$21)/100+'02_Inputs'!$B$17*12)/('03_Model'!$B$6*(('02_Inputs'!$B$22)+'03_Model'!$B$12)*(1+'02_Inputs'!$B$21)/100+'02_Inputs'!$B$17*12) | D22: =1-('03_Model'!$B$6*(($A22*D$17+'02_Inputs'!$B$16)+'03_Model'!$B$12)*(1+'02_Inputs'!$B$21)/100+'02_Inputs'!$B$17*12)/('03_Model'!$B$6*(('02_Inputs'!$B$22)+'03_Model'!$B$12)*(1+'02_Inputs'!$B$21)/100+'02_Inputs'!$B$17*12) | E22: =1-('03_Model'!$B$6*(($A22*E$17+'02_Inputs'!$B$16)+'03_Model'!$B$12)*(1+'02_Inputs'!$B$21)/100+'02_Inputs'!$B$17*12)/('03_Model'!$B$6*(('02_Inputs'!$B$22)+'03_Model'!$B$12)*(1+'02_Inputs'!$B$21)/100+'02_Inputs'!$B$17*12) | F22: =1-('03_Model'!$B$6*(($A22*F$17+'02_Inputs'!$B$16)+'03_Model'!$B$12)*(1+'02_Inputs'!$B$21)/100+'02_Inputs'!$B$17*12)/('03_Model'!$B$6*(('02_Inputs'!$B$22)+'03_Model'!$B$12)*(1+'02_Inputs'!$B$21)/100+'02_Inputs'!$B$17*12)
A23: 15 | B23: =1-('03_Model'!$B$6*(($A23*B$17+'02_Inputs'!$B$16)+'03_Model'!$B$12)*(1+'02_Inputs'!$B$21)/100+'02_Inputs'!$B$17*12)/('03_Model'!$B$6*(('02_Inputs'!$B$22)+'03_Model'!$B$12)*(1+'02_Inputs'!$B$21)/100+'02_Inputs'!$B$17*12) | C23: =1-('03_Model'!$B$6*(($A23*C$17+'02_Inputs'!$B$16)+'03_Model'!$B$12)*(1+'02_Inputs'!$B$21)/100+'02_Inputs'!$B$17*12)/('03_Model'!$B$6*(('02_Inputs'!$B$22)+'03_Model'!$B$12)*(1+'02_Inputs'!$B$21)/100+'02_Inputs'!$B$17*12) | D23: =1-('03_Model'!$B$6*(($A23*D$17+'02_Inputs'!$B$16)+'03_Model'!$B$12)*(1+'02_Inputs'!$B$21)/100+'02_Inputs'!$B$17*12)/('03_Model'!$B$6*(('02_Inputs'!$B$22)+'03_Model'!$B$12)*(1+'02_Inputs'!$B$21)/100+'02_Inputs'!$B$17*12) | E23: =1-('03_Model'!$B$6*(($A23*E$17+'02_Inputs'!$B$16)+'03_Model'!$B$12)*(1+'02_Inputs'!$B$21)/100+'02_Inputs'!$B$17*12)/('03_Model'!$B$6*(('02_Inputs'!$B$22)+'03_Model'!$B$12)*(1+'02_Inputs'!$B$21)/100+'02_Inputs'!$B$17*12) | F23: =1-('03_Model'!$B$6*(($A23*F$17+'02_Inputs'!$B$16)+'03_Model'!$B$12)*(1+'02_Inputs'!$B$21)/100+'02_Inputs'!$B$17*12)/('03_Model'!$B$6*(('02_Inputs'!$B$22)+'03_Model'!$B$12)*(1+'02_Inputs'!$B$21)/100+'02_Inputs'!$B$17*12)
A24: 18 | B24: =1-('03_Model'!$B$6*(($A24*B$17+'02_Inputs'!$B$16)+'03_Model'!$B$12)*(1+'02_Inputs'!$B$21)/100+'02_Inputs'!$B$17*12)/('03_Model'!$B$6*(('02_Inputs'!$B$22)+'03_Model'!$B$12)*(1+'02_Inputs'!$B$21)/100+'02_Inputs'!$B$17*12) | C24: =1-('03_Model'!$B$6*(($A24*C$17+'02_Inputs'!$B$16)+'03_Model'!$B$12)*(1+'02_Inputs'!$B$21)/100+'02_Inputs'!$B$17*12)/('03_Model'!$B$6*(('02_Inputs'!$B$22)+'03_Model'!$B$12)*(1+'02_Inputs'!$B$21)/100+'02_Inputs'!$B$17*12) | D24: =1-('03_Model'!$B$6*(($A24*D$17+'02_Inputs'!$B$16)+'03_Model'!$B$12)*(1+'02_Inputs'!$B$21)/100+'02_Inputs'!$B$17*12)/('03_Model'!$B$6*(('02_Inputs'!$B$22)+'03_Model'!$B$12)*(1+'02_Inputs'!$B$21)/100+'02_Inputs'!$B$17*12) | E24: =1-('03_Model'!$B$6*(($A24*E$17+'02_Inputs'!$B$16)+'03_Model'!$B$12)*(1+'02_Inputs'!$B$21)/100+'02_Inputs'!$B$17*12)/('03_Model'!$B$6*(('02_Inputs'!$B$22)+'03_Model'!$B$12)*(1+'02_Inputs'!$B$21)/100+'02_Inputs'!$B$17*12) | F24: =1-('03_Model'!$B$6*(($A24*F$17+'02_Inputs'!$B$16)+'03_Model'!$B$12)*(1+'02_Inputs'!$B$21)/100+'02_Inputs'!$B$17*12)/('03_Model'!$B$6*(('02_Inputs'!$B$22)+'03_Model'!$B$12)*(1+'02_Inputs'!$B$21)/100+'02_Inputs'!$B$17*12)
A26: Read grid 2 like this: the saving flips negative once the average spot plus your markup exceeds the fixed energy component. THAT is the break-even, and it is a level effect, not an optimisation effect.

Sheet 05_SQL_Actuals
A1: MEASURED OUTPUT FROM THE SQL PIPELINE — the model must reconcile to this
A2: Produced by 03_gold.sql + 04_tariff_backtest.py. Refresh by rerunning the pipeline, never by editing these cells.
A3: MEASURED SCALARS — the model reconciles against these, not against annualised volumes
A4: Measured average day-ahead spot | B4: 8.8089 | C4: ct/kWh, mean over all priced intervals
A5: Measured commodity share of net price | B5: 0.3278 | C5: share — the '~40%' insight, measured
A6: Measured realised/average ratio (no battery) | B6: 1.0682 | C6: x — >1 means unoptimised load
A9: A · Per-customer summary (gold_customer_summary)
A10: malo_id | B10: segment | C10: tariff_type | D10: dso_name | E10: kwh_observed | F10: dyn_bill_observed | G10: fix_bill_observed | H10: realised_to_average_ratio | I10: controllable_kw | J10: gross_margin_eur_year | K10: cac_payback_months
A11: 53850487964 | B11: PV_battery | C11: FIXED | D11: Rheinnetz | E11: 599.4 | F11: 236.58 | G11: 265.82 | H11: 1.0783 | I11: 6.3 | J11: 696.68 | K11: 7.2
A12: 59028472520 | B12: PV_battery | C12: DYNAMIC | D12: Netze BW | E12: 607.6 | F12: 239.78 | G12: 269.47 | H12: 1.0776 | I12: 7.5 | J12: 778.53 | K12: 6.5
A13: 64853594978 | B13: PV_battery | C13: FIXED | D13: Netz Leipzig | E13: 694.6 | F13: 274.15 | G13: 308.08 | H13: 1.0777 | I13: 7.5 | J13: 784.89 | K13: 6.4
A14: 65400074314 | B14: PV_battery | C14: DYNAMIC | D14: Netze BW | E14: 685.5 | F14: 270.46 | G14: 304.02 | H14: 1.0772 | I14: 2.5 | J14: 459.22 | K14: 11
A15: 02378447181 | B15: PV_battery_HP | C15: DYNAMIC | D15: Netz Leipzig | E15: 6920.3 | F15: 2719.8 | G15: 3069.26 | H15: 1.0622 | I15: 6.8 | J15: 1190.61 | K15: 4.2
A16: 07412179067 | B16: PV_battery_HP | C16: DYNAMIC | D16: Netze BW | E16: 6279.7 | F16: 2468.31 | G16: 2785.13 | H16: 1.0624 | I16: 9.3 | J16: 1306.35 | K16: 3.9
A17: 13733263538 | B17: PV_battery_HP | C17: DYNAMIC | D17: SWM Infrastruktur | E17: 6558.2 | F17: 2577.6 | G17: 2908.65 | H17: 1.0621 | I17: 8 | J17: 1245.43 | K17: 4
A18: 15096034392 | B18: PV_battery_HP | C18: DYNAMIC | D18: Stromnetz Berlin | E18: 6815.8 | F18: 2678.59 | G18: 3022.9 | H18: 1.0621 | I18: 6.8 | J18: 1182.98 | K18: 4.3
A19: 19554292257 | B19: PV_battery_HP | C19: DYNAMIC | D19: Stromnetz Berlin | E19: 5240.8 | F19: 2059.82 | G19: 2324.35 | H19: 1.0624 | I19: 8 | J19: 1149.26 | K19: 4.4
A20: 45855425961 | B20: PV_battery_HP | C20: DYNAMIC | D20: Netz Leipzig | E20: 4881.3 | F20: 1918.17 | G20: 2164.91 | H20: 1.0617 | I20: 5.5 | J20: 960.51 | K20: 5.2
A21: 50096239004 | B21: PV_battery_HP | C21: FIXED | D21: Netz Leipzig | E21: 4776.6 | F21: 1877.5 | G21: 2118.49 | H21: 1.0622 | I21: 6.8 | J21: 1034.12 | K21: 4.9
A22: 66586652381 | B22: PV_battery_HP | C22: FIXED | D22: Rheinnetz | E22: 5256.7 | F22: 2065.58 | G22: 2331.41 | H22: 1.0614 | I22: 10.5 | J22: 1312.92 | K22: 3.8
... A38: 58143754480 | B38: no_hardware | C38: DYNAMIC | D38: Netz Leipzig | E38: 903.8 | F38: 356.62 | G38: 400.85 | H38: 1.0773 | I38: 0 | J38: 312.66 | K38: 16.1
A41: B · Backtest by segment: A fixed / B dynamic / C dynamic+battery
A42: segment | B42: customers | C42: kwh | D42: A | E42: B | F42: C | G42: ratio_B | H42: ratio_C | I42: cycles | J42: shifted | K42: B_vs_A_pct | L42: C_vs_A_pct | M42: C_vs_B_eur
A43: PV_battery_HP_EV | B43: 7 | C43: 56051.84 | D43: 25067.62 | E43: 22288.78 | F43: 22158.54 | G43: 1.06 | H43: 0.98 | I43: 108.54 | J43: 6754.14 | K43: 11.09 | L43: 11.6 | M43: 130.24
A44: PV_battery_HP | B44: 9 | C44: 51605.11 | D44: 23154.84 | E44: 20632.23 | F44: 20481.21 | G44: 1.06 | H44: 0.95 | I44: 104.41 | J44: 8091.26 | K44: 10.89 | L44: 11.55 | M44: 151.02
A45: no_hardware | B45: 2 | C45: 1799.56 | D45: 857.53 | E45: 787.96 | F45: 787.96 | G45: 1.08 | H45: 1.08 | I45: 0 | J45: 0 | K45: 8.11 | L45: 8.11 | M45: 0
A46: PV_only | B46: 6 | C46: 3987.09 | D46: 1946.53 | E46: 1807.29 | F46: 1807.29 | G46: 1.08 | H46: 1.08 | I46: 0 | J46: 0 | K46: 7.15 | L46: 7.15 | M46: 0
A47: PV_battery | B47: 4 | C47: 2587.07 | D47: 1266.2 | E47: 1176.84 | F47: 1176.12 | G47: 1.08 | H47: 0.9 | I47: 21.23 | J47: 715.62 | K47: 7.06 | L47: 7.11 | M47: 0.72
A50: C · Data quality scorecard — publish this next to every number
A51: metric | B51: val | C51: unit
A52: meter_rows_landed | B52: 257061 | C52: rows
A53: meter_rows_rejected | B53: 18566 | C53: rows
A54: meter_rows_deduplicated | B54: 2786 | C54: rows
A55: meter_rows_usable | B55: 235709 | C55: rows
A56: meter_usable_pct | B56: 91.69 | C56: %
A57: orphan_malo_rows_dropped | B57: 17024 | C57: rows
A58: customers_with_malformed_malo_id | B58: 4 | C58: customers
A59: customers_reporting_kW_not_kWh | B59: 3 | C59: customers
A60: substitute_value_share | B60: 2.09 | C60: %
A61: export_leaked_into_import_kwh | B61: 448.1 | C61: kWh
...

Sheet 06_Dashboard
A1: DASHBOARD — the six numbers you would actually present
A3: Grid import (billed volume) | B3: ='03_Model'!$B$6 | C3: kWh/yr | D3: TRAFFIC LIGHTS
A5: Commodity share of net price | B5: ='03_Model'!$B$15 | C5: share | D5: LTV/CAC above 3.0 | E5: =IF('03_Model'!$B$39>=3,"GREEN","AMBER")
A7: Customer saving vs fixed | B7: ='03_Model'!$B$21 | C7: EUR/yr | D7: CAC payback under 18 mo | E7: =IF('03_Model'!$B$36<=18,"GREEN","AMBER")
A9: Customer saving vs fixed, % | B9: ='03_Model'!$B$22 | C9: share | D9: Customer actually saves | E9: =IF('03_Model'!$B$21>0,"GREEN","RED — do not sell this")
A11: Supplier gross margin | B11: ='03_Model'!$B$33 | C11: EUR/yr | D11: Saving claim defensible | E11: =IF('03_Model'!$B$22<='03_Model'!$B$16*3,"GREEN","AMBER — check the maths")
A13: CAC payback | B13: ='03_Model'!$B$36 | C13: months
A15: LTV / CAC | B15: ='03_Model'!$B$39 | C15: x
A20: Bill by scenario and segment (measured, from the backtest)
A21: segment | B21: A | C21: B | D21: C
A22: PV_battery_HP_EV | B22: 25067.62 | C22: 22288.78 | D22: 22158.54
A23: PV_battery_HP | B23: 23154.84 | C23: 20632.23 | D23: 20481.21
A24: no_hardware | B24: 857.53 | C24: 787.96 | D24: 787.96
A25: PV_only | B25: 1946.53 | C25: 1807.29 | D25: 1807.29
A26: PV_battery | B26: 1266.2 | C26: 1176.84 | D26: 1176.12

Sheet 07_Checks
A1: CHECKS — try to break your own model before someone else does
A2: Check | B2: Result | C2: Verdict | D2: Why it matters
A3: Volume identity: import + self-consumed = consumption | B3: ='03_Model'!$B$6+'03_Model'!$B$5-'02_Inputs'!$B$4 | C3: =IF(ABS('03_Model'!$B$6+'03_Model'!$B$5-'02_Inputs'!$B$4)<0.01,"PASS","CHECK") | D3: If this is not zero the volume logic double-counts or loses energy.
A4: Self-sufficiency stays below 100% (PV cannot cover the night) | B4: ='03_Model'!$B$5/'02_Inputs'!$B$4 | C4: =IF('03_Model'!$B$5/'02_Inputs'!$B$4<0.85,"PASS","CHECK — impossible autarky") | D4: The first draft of this model reported ZERO grid import because self-consumption was capped only by total consumption. Solar does not generate at night; the Autarkiegrad cap is the physics.
A5: Grid import is a positive, billable volume | B5: ='03_Model'!$B$6 | C5: =IF('03_Model'!$B$6>0,"PASS","CHECK — nothing to bill") | D5: A customer with zero grid import generates no energy margin at all.
A6: Commodity share is in the 25–45% range for Germany | B6: ='03_Model'!$B$15 | C6: =IF(AND('03_Model'!$B$15>0.25,'03_Model'!$B$15<0.45),"PASS","CHECK") | D6: Outside this band you have mis-entered the grid fee or levies.
A7: Saving does not exceed the theoretical maximum | B7: ='03_Model'!$B$22 | C7: =IF('03_Model'!$B$22<0.30,"PASS","CHECK") | D7: A >30% saving on a German bill is almost always a modelling error.
A8: Gross margin is positive | B8: ='03_Model'!$B$33 | C8: =IF('03_Model'!$B$33>0,"PASS","CHECK") | D8: A negative-margin customer should not be acquired at all.
A9: Flex revenue is not the whole business case | B9: ='02_Inputs'!$B$27*'02_Inputs'!$B$12/'03_Model'!$B$29 | C9: =IF('02_Inputs'!$B$27*'02_Inputs'!$B$12/'03_Model'!$B$29<0.7,"PASS","CHECK — the case rests on the least certain input") | D9: Flex revenue is the weakest assumption. If it dominates, say so out loud.
A10: Input spot price matches the measured pipeline (±2%) | B10: ='05_SQL_Actuals'!$B$4 | C10: =IF(ABS('05_SQL_Actuals'!$B$4-'02_Inputs'!$B$14)/'05_SQL_Actuals'!$B$4<0.02,"PASS","CHECK") | D10: Reconcile the model to MEASURED SCALARS, not to annualised volumes. The observed window is Feb–Apr and seasonally biased, so volume cannot reconcile — but a price average can, exactly.
A11: Commodity share matches the measured pipeline (±3pp) | B11: ='05_SQL_Actuals'!$B$5 | C11: =IF(ABS('05_SQL_Actuals'!$B$5-'03_Model'!$B$15)<0.03,"PASS","CHECK") | D11: If the model and the pipeline disagree on the price stack, one of them has the wrong grid fee or levy.
A14: If any verdict reads CHECK, the model is not presentable. Fix it or state the caveat in the first sentence of your memo — never in a footnote.
